Workbook

Sheet 1학기
A1: 2026학년도 1학기 학사일정
A3: 월 | B3: 주 | C3: 날짜 | D3: 수업일수 | G3: 수업시수 | J3: 행사 및 요일별 수업시수 | AE3: 창의적체험활동
D4: 1 학 년 | E4: 2 학 년 | F4: 3 학 년 | G4: 1 학 년 | H4: 2 학 년 | I4: 3 학 년 | J4: 월(6교시) | N4: 화(7교시) | R4: 수(6교시) | V4: 목(7교시) | Z4: 금(6교시) | AD4: 토요 프로 그램 | AE4: 자 율 | AI4: 동 아 리 | AJ4: 봉 사 | AK4: 진로 | AL4: 별도행사 | AM4: 비 고
J6: 날짜 | K6: 시수 | N6: 날짜 | O6: 시수 | R6: 날짜 | S6: 시수 | V6: 날짜 | W6: 시수 | Z6: 날짜 | AA6: 시수 | AE6: 적응 | AF6: 자치 | AG6: 행사 | AH6: 창특
A7: 3 | B7: 1 | C7: 2~6 | D7: =COUNT(K10,O10,S10,W10,AA10) -> 4 | E7: =COUNT(L10,P10,T10,X10,AB10) -> 4 | F7: =COUNT(M10,Q10,U10,Y10,AC10) -> 4 | G7: =SUM(O10,K10,S10,W10,AA10,) -> 26 | H7: =SUM(P10,L10,T10,X10,AB10,) -> 26 | I7: =SUM(M10,Q10,U10,Y10,AC10,) -> 26 | J7: 2 | N7: 3 | O7: 입학식 | R7: 4 | V7: 5 | Z7: 6
K8: 대체공휴일 | O8: 개학식
O9: 개학식
O10: 7 | P10: 7 | Q10: 7 | S10: 6 | T10: 6 | U10: 6 | W10: 7 | X10: 7 | Y10: 7 | AA10: 6 | AB10: 6 | AC10: 6
B11: 2 | C11: 9~13 | D11: =COUNT(K14,O14,S14,W14,AA14) -> 5 | E11: =COUNT(L14,P14,T14,X14,AB14) -> 5 | F11: =COUNT(M14,Q14,U14,Y14,AC14) -> 5 | G11: =SUM(K14,O14,S14,W14,AA14) -> 32 | H11: =SUM(L14,P14,T14,X14,AB14) -> 32 | I11: =SUM(M14,Q14,U14,Y14,AC14) -> 32 | J11: 9 | N11: 10 | R11: 11 | V11: 12 | Z11: 13
K14: 6 | L14: 6 | M14: 6 | O14: 7 | P14: 7 | Q14: 7 | S14: 6 | T14: 6 | U14: 6 | W14: 7 | X14: 7 | Y14: 7 | AA14: 6 | AB14: 6 | AC14: 6
B15: 3 | C15: 16~20 | D15: =COUNT(K18,O18,S18,W18,AA18) -> 5 | E15: =COUNT(L18,P18,T18,X18,AB18) -> 5 | F15: =COUNT(M18,Q18,U18,Y18,AC18) -> 5 | G15: =SUM(K18,O18,S18,W18,AA18) -> 32 | H15: =SUM(L18,P18,T18,X18,AB18) -> 32 | I15: =SUM(M18,Q18,U18,Y18,AC18) -> 32 | J15: 16 | N15: 17 | R15: 18 | S15: 학부모총회 | V15: 19 | Z15: 20 | AM15: *학부모총회 5분 단축수업 운영
K18: 6 | L18: 6 | M18: 6 | O18: 7 | P18: 7 | Q18: 7 | S18: 6 | T18: 6 | U18: 6 | W18: 7 | X18: 7 | Y18: 7 | AA18: 6 | AB18: 6 | AC18: 6
B19: 4 | C19: 23~27 | D19: =COUNT(K22,O22,S22,W22,AA22) -> 5 | E19: =COUNT(L22,P22,T22,X22,AB22) -> 5 | F19: =COUNT(M22,Q22,U22,Y22,AC22) -> 5 | G19: =SUM(K22,O22,S22,W22,AA22) -> 32 | H19: =SUM(L22,P22,T22,X22,AB22) -> 32 | I19: =SUM(M22,Q22,U22,Y22,AC22) -> 32 | J19: 23 | N19: 24 | O19: 전국연합학력평가 | R19: 25 | V19: 26 | Z19: 27
O20: 전국연합학력평가
O21: 전국연합학력평가
K22: 6 | L22: 6 | M22: 6 | O22: 7 | P22: 7 | Q22: 7 | S22: 6 | T22: 6 | U22: 6 | W22: 7 | X22: 7 | Y22: 7 | AA22: 6 | AB22: 6 | AC22: 6
B23: 5 | C23: 30~31 | D23: =COUNT(K26,O26,S26,W26,AA26) -> 2 | E23: =COUNT(L26,P26,T26,X26,AB26) -> 2 | F23: =COUNT(M26,Q26,U26,Y26,AC26) -> 2 | G23: =SUM(K26,O26,S26,W26,AA26) -> 13 | H23: =SUM(L26,P26,T26,X26,AB26) -> 13 | I23: =SUM(M26,Q26,U26,Y26,AC26) -> 13 | J23: 30 | N23: 31
K26: 6 | L26: 6 | M26: 6 | O26: 7 | P26: 7 | Q26: 7
A27: 4 | B27: 5 | C27: 1~3 | D27: =COUNT(K30,O30,S30,W30,AA30) -> 3 | E27: =COUNT(L30,P30,T30,X30,AB30) -> 3 | F27: =COUNT(M30,Q30,U30,Y30,AC30) -> 3 | G27: =SUM(K30,O30,S30,W30,AA30) -> 19 | H27: =SUM(L30,P30,T30,X30,AB30) -> 19 | I27: =SUM(M30,Q30,U30,Y30,AC30) -> 19 | R27: 1 | S27: 1학년 수련회 | V27: 2 | W27: 1학년 수련회 | Z27: 3 | AA27: 1학년 수련회
AA28: 2학년현장체험학습
S30: 6 | T30: 6 | U30: 6 | W30: 7 | X30: 7 | Y30: 7 | AA30: 6 | AB30: 6 | AC30: 6
B31: 6 | C31: 6~10 | D31: =COUNT(K34,O34,S34,W34,AA34) -> 5 | E31: =COUNT(L34,P34,T34,X34,AB34) -> 5 | F31: =COUNT(M34,Q34,U34,Y34,AC34) -> 5 | G31: =SUM(K34,O34,S34,W34,AA34) -> 32 | H31: =SUM(L34,P34,T34,X34,AB34) -> 32 | I31: =SUM(M34,Q34,U34,Y34,AC34) -> 32 | J31: 6 | N31: 7 | R31: 8 | V31: 9 | Z31: 10
K34: 6 | L34: 6 | M34: 6 | O34: 7 | P34: 7 | Q34: 7 | S34: 6 | T34: 6 | U34: 6 | W34: 7 | X34: 7 | Y34: 7 | AA34: 6 | AB34: 6 | AC34: 6
B35: 7 | C35: 13~17 | D35: =COUNT(K38,O38,S38,W38,AA38) -> 5 | E35: =COUNT(L38,P38,T38,X38,AB38) -> 5 | F35: =COUNT(M38,Q38,U38,Y38,AC38) -> 5 | G35: =SUM(K38,O38,S38,W38,AA38) -> 32 | H35: =SUM(L38,P38,T38,X38,AB38) -> 32 | I35: =SUM(M38,Q38,U38,Y38,AC38) -> 32 | J35: 13 | N35: 14 | R35: 15 | V35: 16 | Z35: 17
K38: 6 | L38: 6 | M38: 6 | O38: 7 | P38: 7 | Q38: 7 | S38: 6 | T38: 6 | U38: 6 | W38: 7 | X38: 7 | Y38: 7 | AA38: 6 | AB38: 6 | AC38: 6
B39: 8 | C39: 20~24 | D39: =COUNT(K42,O42,S42,W42,AA42) -> 5 | E39: =COUNT(L42,P42,T42,X42,AB42) -> 5 | F39: =COUNT(M42,Q42,U42,Y42,AC42) -> 5 | G39: =SUM(K42,O42,S42,W42,AA42) -> 23 | H39: =SUM(L42,P42,T42,X42,AB42) -> 23 | I39: =SUM(M42,Q42,U42,Y42,AC42) -> 25 | J39: 20 | N39: 21 | R39: 22 | V39: 23 | W39: 1 차 지필 | X39: 수업 | Y39: 1 차 지필 | Z39: 24 | AA39: 1 차 지필 | AB39: 수업 | AC39: 1차 지필 | AM39: 지필평가기간 시간표 운영 23일 : 7월 9일 목 5교시 24일 : 7월 9일 목 6교시
K42: 6 | L42: 6 | M42: 6 | O42: 7 | P42: 7 | Q42: 7 | S42: 6 | T42: 6 | U42: 6 | W42: 2 | X42: 2 | Y42: 3 | AA42: 2 | AB42: 2 | AC42: 3
B43: 9 | C43: 27~30 | D43: =COUNT(K46,O46,S46,W46,AA46) -> 4 | E43: =COUNT(L46,P46,T46,X46,AB46) -> 4 | F43: =COUNT(M46,Q46,U46,Y46,AC46) -> 4 | G43: =SUM(K46,O46,S46,W46,AA46) -> 13 | H43: =SUM(L46,P46,T46,X46,AB46) -> 13 | I43: =SUM(M46,Q46,U46,Y46,AC46) -> 16 | J43: 27 | N43: 28 | R43: 29 | V43: 30 | AM43: 지필평가기간 시간표 운영 27일: 7월 9일 목 7교시 28일: 7월 10일 금 1교시 29일: 7월 10일 금 2교시
K44: 1차지필 | O44: 1차지필 | S44: 1차지필
K46: 2 | L46: 2 | M46: 3 | O46: 2 | P46: 2 | Q46: 3 | S46: 2 | T46: 2 | U46: 3 | W46: 7 | X46: 7 | Y46: 7
A47: 5 | B47: 9 | C47: 1 | D47: =COUNT(K50,O50,S50,W50,AA50) -> 0 | E47: =COUNT(L50,P50,T50,X50,AB50) -> 0 | F47: =COUNT(M50,Q50,U50,Y50,AC50) -> 0 | G47: =SUM(K50,O50,S50,W50,AA50) -> 0 | H47: =SUM(L50,P50,T50,X50,AB50) -> 0 | I47: =SUM(M50,Q50,U50,Y50,AC50) -> 0 | Z47: 1
AA48: 노동절
B51: 10 | C51: 4~8 | D51: =COUNT(K54,O54,S54,W54,AA54) -> 3 | E51: =COUNT(L54,P54,T54,X54,AB54) -> 3 | F51: =COUNT(M54,Q54,U54,Y54,AC54) -> 3 | G51: =SUM(K54,O54,S54,W54,AA54) -> 19 | H51: =SUM(L54,P54,T54,X54,AB54) -> 19 | I51: =SUM(M54,Q54,U54,Y54,AC54) -> 19 | J51: 4 | N51: 5 | R51: 6 | V51: 7 | Z51: 8 | AA51: 체육한마당
K52: 재량휴업일 | O52: 어린이날
W53: 전국연합학력평가
S54: 6 | T54: 6 | U54: 6 | W54: 7 | X54: 7 | Y54: 7 | AA54: 6 | AB54: 6 | AC54: 6
B55: 11 | C55: 11~15 | D55: =COUNT(K58,O58,S58,W58,AA58) -> 5 | E55: =COUNT(L58,P58,T58,X58,AB58) -> 5 | F55: =COUNT(M58,Q58,U58,Y58,AC58) -> 5 | G55: =SUM(K58,O58,S58,W58,AA58) -> 32 | H55: =SUM(L58,P58,T58,X58,AB58) -> 32 | I55: =SUM(M58,Q58,U58,Y58,AC58) -> 32 | J55: 11 | N55: 12 | R55: 13 | V55: 14 | Z55: 15
K58: 6 | L58: 6 | M58: 6 | O58: 7 | P58: 7 | Q58: 7 | S58: 6 | T58: 6 | U58: 6 | W58: 7 | X58: 7 | Y58: 7 | AA58: 6 | AB58: 6 | AC58: 6
B59: 12 | C59: 18~22 | D59: =COUNT(K62,O62,S62,W62,AA62) -> 5 | E59: =COUNT(L62,P62,T62,X62,AB62) -> 5 | F59: =COUNT(M62,Q62,U62,Y62,AC62) -> 5 | G59: =SUM(K62,O62,S62,W62,AA62) -> 32 | H59: =SUM(L62,P62,T62,X62,AB62) -> 32 | I59: =SUM(M62,Q62,U62,Y62,AC62) -> 32 | J59: 18 | N59: 19 | R59: 20 | V59: 21 | Z59: 22 | AM59: *1,2,3학년 학부모 상담주간
K62: 6 | L62: 6 | M62: 6 | O62: 7 | P62: 7 | Q62: 7 | S62: 6 | T62: 6 | U62: 6 | W62: 7 | X62: 7 | Y62: 7 | AA62: 6 | AB62: 6 | AC62: 6
...

Sheet 2학기
A1: 2026학년도 2학기 학사일정
A2: 월 | B2: 주 | C2: 날짜 | D2: 수업일수 | G2: 수업시수 | J2: 행사 및 요일별 수업시수 | AE2: 창의적체험활동
D3: 1 학 년 | E3: 2 학 년 | F3: 3 학 년 | G3: 1 학 년 | H3: 2 학 년 | I3: 3 학 년 | J3: 월(6교시) | N3: 화(7교시) | R3: 수(6교시) | V3: 목(7교시) | Z3: 금(6교시) | AD3: 토요 | AE3: 자 율 | AI3: 동 아 리 | AJ3: 봉 사 | AK3: 진로 | AL3: 별도행사 | AM3: 비 고
AD4: 프로
J5: 날짜 | K5: 시수 | N5: 날짜 | O5: 시수 | R5: 날짜 | S5: 시수 | V5: 날짜 | W5: 시수 | Z5: 날짜 | AA5: 시수 | AD5: 그램 | AE5: 적응 | AF5: 자치 | AG5: 행사 | AH5: 창특
A6: 8 | B6: 1 | C6: 11~15 | D6: =COUNT(K9,O9,S9,W9,AA9) -> 0 | E6: =COUNT(L9,P9,T9,X9,AB9) -> 0 | F6: =COUNT(M9,Q9,U9,Y9,AC9) -> 0 | G6: =K9+O9+S9+W9+AA9 -> 0 | H6: =SUM(L9,P9,T9,X9,AB9) -> 0 | I6: =SUM(M9,Q9,U9,Y9,AC9) -> 0 | J6: 11 | N6: 12 | R6: 13 | V6: 14 | Z6: 15
AA7: 광복절
B10: 1 | C10: 17~21 | D10: =COUNT(K13,O13,S13,W13,AA13) -> 4 | E10: =COUNT(L13,P13,T13,X13,AB13) -> 4 | F10: =COUNT(M13,Q13,U13,Y13,AC13) -> 4 | G10: =SUM(K13,O13,S13,W13,AA13) -> 26 | H10: =SUM(L13,P13,T13,X13,AB13) -> 26 | I10: =SUM(M13,Q13,U13,Y13,AC13) -> 26 | J10: 17 | N10: 18 | O10: 개학 | R10: 19 | V10: 20 | Z10: 21
K11: 대체공휴일 | O11: 개학
O12: 개학
O13: 7 | P13: 7 | Q13: 7 | S13: 6 | T13: 6 | U13: 6 | W13: 7 | X13: 7 | Y13: 7 | AA13: 6 | AB13: 6 | AC13: 6
B14: 2 | C14: 24~28 | D14: =COUNT(K17,O17,S17,W17,AA17) -> 5 | E14: =COUNT(L17,P17,T17,X17,AB17) -> 5 | F14: =COUNT(M17,Q17,U17,Y17,AC17) -> 5 | G14: =SUM(K17,O17,S17,W17,AA17) -> 32 | H14: =SUM(L17,P17,T17,X17,AB17) -> 32 | I14: =SUM(M17,Q17,U17,Y17,AC17) -> 32 | J14: 24 | N14: 25 | R14: 26 | V14: 27 | Z14: 28
K17: 6 | L17: 6 | M17: 6 | O17: 7 | P17: 7 | Q17: 7 | S17: 6 | T17: 6 | U17: 6 | W17: 7 | X17: 7 | Y17: 7 | AA17: 6 | AB17: 6 | AC17: 6
B18: 3 | C18: 31 | D18: =COUNT(K21,O21,S21,W21,AA21) -> 1 | E18: =COUNT(L21,P21,T21,X21,AB21) -> 1 | F18: =COUNT(M21,Q21,U21,Y21,AC21) -> 1 | G18: =SUM(K21,O21,S21,W21,AA21) -> 6 | H18: =SUM(L21,P21,T21,X21,AB21) -> 6 | I18: =SUM(M21,Q21,U21,Y21,AC21) -> 6 | J18: 31 | AM18: *3학년 학부모 상담주간
K21: 6 | L21: 6 | M21: 6
A22: 9 | B22: 3 | C22: 1~4 | D22: =COUNT(K25,O25,S25,W25,AA25) -> 4 | E22: =COUNT(L25,P25,T25,X25,AB25) -> 4 | F22: =COUNT(M25,Q25,U25,Y25,AC25) -> 4 | G22: =SUM(K25,O25,S25,W25,AA25) -> 27 | H22: =SUM(L25,P25,T25,X25,AB25) -> 27 | I22: =SUM(M25,Q25,U25,Y25,AC25) -> 27 | N22: 1 | R22: 2 | S22: 전국연합학력평가 | V22: 3 | Z22: 4 | AM22: *3학년 학부모 상담주간 시간표 변경 운영 2일: 7교시(10월27일 화6교시)
S23: 전국연합학력평가
S24: 대수능모의평가
O25: 7 | P25: 7 | Q25: 7 | S25: 7 | T25: 7 | U25: 7 | W25: 7 | X25: 7 | Y25: 7 | AA25: 6 | AB25: 6 | AC25: 6
B26: 4 | C26: 7~11 | D26: =COUNT(K29,O29,S29,W29,AA29) -> 5 | E26: =COUNT(L29,P29,T29,X29,AB29) -> 5 | F26: =COUNT(M29,Q29,U29,Y29,AC29) -> 5 | G26: =SUM(K29,O29,S29,W29,AA29) -> 32 | H26: =SUM(L29,P29,T29,X29,AB29) -> 32 | I26: =SUM(M29,Q29,U29,Y29,AC29) -> 32 | J26: 7 | N26: 8 | R26: 9 | V26: 10 | Z26: 11
K29: 6 | L29: 6 | M29: 6 | O29: 7 | P29: 7 | Q29: 7 | S29: 6 | T29: 6 | U29: 6 | W29: 7 | X29: 7 | Y29: 7 | AA29: 6 | AB29: 6 | AC29: 6
B30: 5 | C30: 14~18 | D30: =COUNT(K33,O33,S33,W33,AA33) -> 5 | E30: =COUNT(L33,P33,T33,X33,AB33) -> 5 | F30: =COUNT(M33,Q33,U33,Y33,AC33) -> 5 | G30: =SUM(K33,O33,S33,W33,AA33) -> 32 | H30: =SUM(L33,P33,T33,X33,AB33) -> 32 | I30: =SUM(M33,Q33,U33,Y33,AC33) -> 32 | J30: 14 | N30: 15 | R30: 16 | V30: 17 | Z30: 18
K33: 6 | L33: 6 | M33: 6 | O33: 7 | P33: 7 | Q33: 7 | S33: 6 | T33: 6 | U33: 6 | W33: 7 | X33: 7 | Y33: 7 | AA33: 6 | AB33: 6 | AC33: 6
B34: 6 | C34: 21~25 | D34: =COUNT(K37,O37,S37,W37,AA37) -> 3 | E34: =COUNT(L37,P37,T37,X37,AB37) -> 3 | F34: =COUNT(M37,Q37,U37,Y37,AC37) -> 3 | G34: =SUM(K37,O37,S37,W37,AA37) -> 19 | H34: =SUM(L37,P37,T37,X37,AB37) -> 19 | I34: =SUM(M37,Q37,U37,Y37,AC37) -> 19 | J34: 21 | N34: 22 | R34: 23 | V34: 24 | Z34: 25
W35: 추석연휴 | AA35: 추석
K37: 6 | L37: 6 | M37: 6 | O37: 7 | P37: 7 | Q37: 7 | S37: 6 | T37: 6 | U37: 6
B38: 7 | C38: 28~30 | D38: =COUNT(K41,O41,S41,W41,AA41) -> 3 | E38: =COUNT(L41,P41,T41,X41,AB41) -> 3 | F38: =COUNT(M41,Q41,U41,Y41,AC41) -> 3 | G38: =SUM(K41,O41,S41,W41,AA41) -> 19 | H38: =SUM(L41,P41,T41,X41,AB41) -> 19 | I38: =SUM(M41,Q41,U41,Y41,AC41) -> 19 | J38: 28 | N38: 29 | R38: 30
K41: 6 | L41: 6 | M41: 6 | O41: 7 | P41: 7 | Q41: 7 | S41: 6 | T41: 6 | U41: 6
A42: 10 | B42: 7 | C42: 1~2 | D42: =COUNT(K45,O45,S45,W45,AA45) -> 2 | E42: =COUNT(L45,P45,T45,X45,AB45) -> 2 | F42: =COUNT(M45,Q45,U45,Y45,AC45) -> 2 | G42: =SUM(K45,O45,S45,W45,AA45) -> 13 | H42: =SUM(L45,P45,T45,X45,AB45) -> 13 | I42: =SUM(M45,Q45,U45,Y45,AC45) -> 13 | V42: 1 | Z42: 2
W45: 7 | X45: 7 | Y45: 7 | AA45: 6 | AB45: 6 | AC45: 6
B46: 8 | C46: 5~9 | D46: =COUNT(K49,O49,S49,W49,AA49) -> 3 | E46: =COUNT(L49,P49,T49,X49,AB49) -> 3 | F46: =COUNT(M49,Q49,U49,Y49,AC49) -> 3 | G46: =SUM(K49,O49,S49,W49,AA49) -> 20 | H46: =SUM(L49,P49,T49,X49,AB49) -> 20 | I46: =SUM(M49,Q49,U49,Y49,AC49) -> 20 | J46: 5 | N46: 6 | R46: 7 | V46: 8 | Z46: 9
K47: 대체공휴일 | AA47: 한글날
O49: 7 | P49: 7 | Q49: 7 | S49: 6 | T49: 6 | U49: 6 | W49: 7 | X49: 7 | Y49: 7
B50: 9 | C50: 12~16 | D50: =COUNT(K53,O53,S53,W53,AA53) -> 5 | E50: =COUNT(L53,P53,T53,X53,AB53) -> 5 | F50: =COUNT(M53,Q53,U53,Y53,AC53) -> 5 | G50: =SUM(K53,O53,S53,W53,AA53) -> 14 | H50: =SUM(L53,P53,T53,X53,AB53) -> 14 | I50: =SUM(M53,Q53,U53,Y53,AC53) -> 18 | J50: 12 | N50: 13 | R50: 14 | V50: 15 | Z50: 16 | AM50: 지필평가기간 시간표 운영 13일 : 12월29일 목요일 5교시 14일 : 12월29일 목요일 6교시 15일 : 12월29일 목요일 7교시 16일 : 2월3일 수요일 5교시
O51: 1차지필 | S51: 1차지필 | W51: 1차지필 | AA51: 1차지필
K53: 6 | L53: 6 | M53: 6 | O53: 2 | P53: 2 | Q53: 3 | S53: 2 | T53: 2 | U53: 3 | W53: 2 | X53: 2 | Y53: 3 | AA53: 2 | AB53: 2 | AC53: 3
B54: 10 | C54: 19~23 | D54: =COUNT(K57,O57,S53,W57,AA57) -> 5 | E54: =COUNT(L57,P57,T53,X57,AB57) -> 5 | F54: =COUNT(M57,Q57,U53,Y57,AC57) -> 5 | G54: =K57+O57+S57+W57+AA57 -> 32 | H54: =L57+P57+T57+X57+AB57 -> 32 | I54: =M57+Q57+U57+Y57+AC57 -> 32 | J54: 19 | N54: 20 | O54: 전국연합학력평가 | R54: 21 | V54: 22 | Z54: 23 | AM54: *1,2학년 학부모 상담주간
O55: 전국연합학력평가
O56: 전국연합학력평가
K57: 6 | L57: 6 | M57: 6 | O57: 7 | P57: 7 | Q57: 7 | S57: 6 | T57: 6 | U57: 6 | W57: 7 | X57: 7 | Y57: 7 | AA57: 6 | AB57: 6 | AC57: 6
...

Sheet Sheet1

Sheet Sheet2
